Workbook

Sheet Inventory
A1: Category | B1: Product | C1: Stocked | D1: Current Stock | E1: Re_order % | F1: Restock_Alert
A2: Beverages | B2: Coke | C2: 1200 | D2: =C2- SUMIF('Sales Data'!D:D,"Coke",'Sales Data'!F:F) -> 163 | E2: =D2/C2*100 -> 13.583333 | F2: =IF(E2<=5,"Restock Alert",IF(E2>50,"Overstock Alert","Stock Level OK")) -> Stock Level OK
A3: Beverages | B3: Pepsi | C3: 1200 | D3: =C3- SUMIF('Sales Data'!D:D,"Pepsi",'Sales Data'!F:F) -> 237 | E3: =D3/C3*100 -> 19.75 | F3: =IF(E3<=5,"Restock Alert",IF(E3>50,"Overstock Alert","Stock Level OK")) -> Stock Level OK
A4: Beverages | B4: Fanta | C4: 1200 | D4: =C4- SUMIF('Sales Data'!D:D,"Fanta",'Sales Data'!F:F) -> 314 | E4: =D4/C4*100 -> 26.166667 | F4: =IF(E4<=5,"Restock Alert",IF(E4>50,"Overstock Alert","Stock Level OK")) -> Stock Level OK
A5: Beverages | B5: Water | C5: 1200 | D5: =C5- SUMIF('Sales Data'!D:D,"Water",'Sales Data'!F:F) -> 357 | E5: =D5/C5*100 -> 29.75 | F5: =IF(E5<=5,"Restock Alert",IF(E5>50,"Overstock Alert","Stock Level OK")) -> Stock Level OK
A6: Food items | B6: Rice | C6: 2000 | D6: =C6- SUMIF('Sales Data'!D:D,"Rice",'Sales Data'!F:F) -> 66 | E6: =D6/C6*100 -> 3.3 | F6: =IF(E6<=5,"Restock Alert",IF(E6>50,"Overstock Alert","Stock Level OK")) -> Restock Alert
A7: Food items | B7: Beans | C7: 2000 | D7: =C7- SUMIF('Sales Data'!D:D,"Beans",'Sales Data'!F:F) -> 816 | E7: =D7/C7*100 -> 40.8 | F7: =IF(E7<=5,"Restock Alert",IF(E7>50,"Overstock Alert","Stock Level OK")) -> Stock Level OK
A8: Food items | B8: Bread | C8: 2000 | D8: =C8- SUMIF('Sales Data'!D:D,"Bread",'Sales Data'!F:F) -> 196 | E8: =D8/C8*100 -> 9.8 | F8: =IF(E8<=5,"Restock Alert",IF(E8>50,"Overstock Alert","Stock Level OK")) -> Stock Level OK
A9: Food items | B9: Spaghetti | C9: 1200 | D9: =C9- SUMIF('Sales Data'!D:D,"Spaghetti",'Sales Data'!F:F) -> 131 | E9: =D9/C9*100 -> 10.916667 | F9: =IF(E9<=5,"Restock Alert",IF(E9>50,"Overstock Alert","Stock Level OK")) -> Stock Level OK
A10: Snacks | B10: Biscuits | C10: 1000 | D10: =C10- SUMIF('Sales Data'!D:D,"Biscuits",'Sales Data'!F:F) -> 121 | E10: =D10/C10*100 -> 12.1 | F10: =IF(E10<=5,"Restock Alert",IF(E10>50,"Overstock Alert","Stock Level OK")) -> Stock Level OK
A11: Snacks | B11: Chocolate | C11: 1000 | D11: =C11- SUMIF('Sales Data'!D:D,"Chocolate",'Sales Data'!F:F) -> 0 | E11: =D11/C11*100 -> 0 | F11: =IF(E11<=5,"Restock Alert",IF(E11>50,"Overstock Alert","Stock Level OK")) -> Restock Alert
A12: Snacks | B12: Chips | C12: 1000 | D12: =C12- SUMIF('Sales Data'!D:D,"Chips",'Sales Data'!F:F) -> 31 | E12: =D12/C12*100 -> 3.1 | F12: =IF(E12<=5,"Restock Alert",IF(E12>50,"Overstock Alert","Stock Level OK")) -> Restock Alert
A13: Household | B13: Detergent | C13: 1500 | D13: =C13- SUMIF('Sales Data'!D:D,"Detergent",'Sales Data'!F:F) -> 376 | E13: =D13/C13*100 -> 25.066667 | F13: =IF(E13<=5,"Restock Alert",IF(E13>50,"Overstock Alert","Stock Level OK")) -> Stock Level OK
A14: Household | B14: Soap | C14: 2000 | D14: =C14- SUMIF('Sales Data'!D:D,"Soap",'Sales Data'!F:F) -> 210 | E14: =D14/C14*100 -> 10.5 | F14: =IF(E14<=5,"Restock Alert",IF(E14>50,"Overstock Alert","Stock Level OK")) -> Stock Level OK
A15: Household | B15: Toothpaste | C15: 1700 | D15: =C15- SUMIF('Sales Data'!D:D,"Toothpaste",'Sales Data'!F:F) -> 26 | E15: =D15/C15*100 -> 1.5294118 | F15: =IF(E15<=5,"Restock Alert",IF(E15>50,"Overstock Alert","Stock Level OK")) -> Restock Alert
A16: Household | B16: Shampoo | C16: 1000 | D16: =C16- SUMIF('Sales Data'!D:D,"Shampoo",'Sales Data'!F:F) -> 63 | E16: =D16/C16*100 -> 6.3 | F16: =IF(E16<=5,"Restock Alert",IF(E16>50,"Overstock Alert","Stock Level OK")) -> Stock Level OK
A17: Clothing | B17: Cap | C17: 300 | D17: =C17- SUMIF('Sales Data'!D:D,"Cap",'Sales Data'!F:F) -> 133 | E17: =D17/C17*100 -> 44.333333 | F17: =IF(E17<=5,"Restock Alert",IF(E17>50,"Overstock Alert","Stock Level OK")) -> Stock Level OK
A18: Clothing | B18: Jeans | C18: 300 | D18: =C18- SUMIF('Sales Data'!D:D,"Jeans",'Sales Data'!F:F) -> 62 | E18: =D18/C18*100 -> 20.666667 | F18: =IF(E18<=5,"Restock Alert",IF(E18>50,"Overstock Alert","Stock Level OK")) -> Stock Level OK
A19: Clothing | B19: Shoes | C19: 300 | D19: =C19- SUMIF('Sales Data'!D:D,"Shoes",'Sales Data'!F:F) -> 110 | E19: =D19/C19*100 -> 36.666667 | F19: =IF(E19<=5,"Restock Alert",IF(E19>50,"Overstock Alert","Stock Level OK")) -> Stock Level OK
A20: Clothing | B20: T-shirt | C20: 300 | D20: =C20- SUMIF('Sales Data'!D:D,"T-shirt",'Sales Data'!F:F) -> 173 | E20: =D20/C20*100 -> 57.666667 | F20: =IF(E20<=5,"Restock Alert",IF(E20>50,"Overstock Alert","Stock Level OK")) -> Overstock Alert
A21: Clothing | B21: Wristwatch | C21: 200 | D21: =C21- SUMIF('Sales Data'!D:D,"Wristwatch",'Sales Data'!F:F) -> 20 | E21: =D21/C21*100 -> 10 | F21: =IF(E21<=5,"Restock Alert",IF(E21>50,"Overstock Alert","Stock Level OK")) -> Stock Level OK
A22: Electronics | B22: Earphones | C22: 300 | D22: =C22- SUMIF('Sales Data'!D:D,"Earphones",'Sales Data'!F:F) -> 147 | E22: =D22/C22*100 -> 49 | F22: =IF(E22<=5,"Restock Alert",IF(E22>50,"Overstock Alert","Stock Level OK")) -> Stock Level OK
A23: Electronics | B23: Extension Box | C23: 200 | D23: =C23- SUMIF('Sales Data'!D:D,"Extension Box",'Sales Data'!F:F) -> 27 | E23: =D23/C23*100 -> 13.5 | F23: =IF(E23<=5,"Restock Alert",IF(E23>50,"Overstock Alert","Stock Level OK")) -> Stock Level OK
A24: Electronics | B24: LED Bulb | C24: 300 | D24: =C24- SUMIF('Sales Data'!D:D,"LED Bulb",'Sales Data'!F:F) -> 11 | E24: =D24/C24*100 -> 3.6666667 | F24: =IF(E24<=5,"Restock Alert",IF(E24>50,"Overstock Alert","Stock Level OK")) -> Restock Alert
A25: Electronics | B25: Power Bank | C25: 200 | D25: =C25- SUMIF('Sales Data'!D:D,"Power Bank",'Sales Data'!F:F) -> 1 | E25: =D25/C25*100 -> 0.5 | F25: =IF(E25<=5,"Restock Alert",IF(E25>50,"Overstock Alert","Stock Level OK")) -> Restock Alert
A26: Diary | B26: Milk | C26: 1000 | D26: =C26- SUMIF('Sales Data'!D:D,"Milk",'Sales Data'!F:F) -> 311 | E26: =D26/C26*100 -> 31.1 | F26: =IF(E26<=5,"Restock Alert",IF(E26>50,"Overstock Alert","Stock Level OK")) -> Stock Level OK
A27: Food items | B27: Garri | C27: 310 | D27: =C27- SUMIF('Sales Data'!D:D,"Garri",'Sales Data'!F:F) -> 143 | E27: =D27/C27*100 -> 46.129032 | F27: =IF(E27<=5,"Restock Alert",IF(E27>50,"Overstock Alert","Stock Level OK")) -> Stock Level OK
A28: Food items | B28: Palm oil | C28: 310 | D28: =C28- SUMIF('Sales Data'!D:D,"Palm oil",'Sales Data'!F:F) -> 101 | E28: =D28/C28*100 -> 32.580645 | F28: =IF(E28<=5,"Restock Alert",IF(E28>50,"Overstock Alert","Stock Level OK")) -> Stock Level OK
A29: Diary | B29: Butter | C29: 2000 | D29: =C29- SUMIF('Sales Data'!D:D,"Butter",'Sales Data'!F:F) -> 1325 | E29: =D29/C29*100 -> 66.25 | F29: =IF(E29<=5,"Restock Alert",IF(E29>50,"Overstock Alert","Stock Level OK")) -> Overstock Alert
A30: Sports | B30: Skipping Rope | C30: 300 | D30: =C30- SUMIF('Sales Data'!D:D,"Skipping Rope",'Sales Data'!F:F) -> 150 | E30: =D30/C30*100 -> 50 | F30: =IF(E30<=5,"Restock Alert",IF(E30>50,"Overstock Alert","Stock Level OK")) -> Stock Level OK
A31: Food items | B31: Yam flour | C31: 300 | D31: =C31- SUMIF('Sales Data'!D:D,"Yam flour",'Sales Data'!F:F) -> 60 | E31: =D31/C31*100 -> 20 | F31: =IF(E31<=5,"Restock Alert",IF(E31>50,"Overstock Alert","Stock Level OK")) -> Stock Level OK
A32: Household | B32: Broom | C32: 300 | D32: =C32- SUMIF('Sales Data'!D:D,"Broom",'Sales Data'!F:F) -> 110 | E32: =D32/C32*100 -> 36.666667 | F32: =IF(E32<=5,"Restock Alert",IF(E32>50,"Overstock Alert","Stock Level OK")) -> Stock Level OK
A33: Household | B33: Bucket | C33: 300 | D33: =C33- SUMIF('Sales Data'!D:D,"Bucket",'Sales Data'!F:F) -> 110 | E33: =D33/C33*100 -> 36.666667 | F33: =IF(E33<=5,"Restock Alert",IF(E33>50,"Overstock Alert","Stock Level OK")) -> Stock Level OK
A34: Food items | B34: Eggs | C34: 1000 | D34: =C34- SUMIF('Sales Data'!D:D,"Eggs",'Sales Data'!F:F) -> 372 | E34: =D34/C34*100 -> 37.2 | F34: =IF(E34<=5,"Restock Alert",IF(E34>50,"Overstock Alert","Stock Level OK")) -> Stock Level OK
A35: Household | B35: Toilet Paper | C35: 310 | D35: =C35- SUMIF('Sales Data'!D:D,"Toilet Paper",'Sales Data'!F:F) -> 108 | E35: =D35/C35*100 -> 34.83871 | F35: =IF(E35<=5,"Restock Alert",IF(E35>50,"Overstock Alert","Stock Level OK")) -> Stock Level OK
A36: Household | B36: Cooking Gas | C36: 310 | D36: =C36- SUMIF('Sales Data'!D:D,"Cooking Gas",'Sales Data'!F:F) -> 161 | E36: =D36/C36*100 -> 51.935484 | F36: =IF(E36<=5,"Restock Alert",IF(E36>50,"Overstock Alert","Stock Level OK")) -> Overstock Alert
A37: Pharmaceuticals | B37: Antibiotics | C37: 200 | D37: =C37- SUMIF('Sales Data'!D:D,"Antibiotics",'Sales Data'!F:F) -> 38 | E37: =D37/C37*100 -> 19 | F37: =IF(E37<=5,"Restock Alert",IF(E37>50,"Overstock Alert","Stock Level OK")) -> Stock Level OK
A38: Pharmaceuticals | B38: Cough Syrup | C38: 200 | D38: =C38- SUMIF('Sales Data'!D:D,"Cough Syrup",'Sales Data'!F:F) -> 41 | E38: =D38/C38*100 -> 20.5 | F38: =IF(E38<=5,"Restock Alert",IF(E38>50,"Overstock Alert","Stock Level OK")) -> Stock Level OK
A39: Pharmaceuticals | B39: Pain Relief Balm | C39: 200 | D39: =C39- SUMIF('Sales Data'!D:D,"Pain Relief Balm",'Sales Data'!F:F) -> 8 | E39: =D39/C39*100 -> 4 | F39: =IF(E39<=5,"Restock Alert",IF(E39>50,"Overstock Alert","Stock Level OK")) -> Restock Alert
A40: Pharmaceuticals | B40: Paracetamol | C40: 200 | D40: =C40- SUMIF('Sales Data'!D:D,"Paracetamol",'Sales Data'!F:F) -> 6 | E40: =D40/C40*100 -> 3 | F40: =IF(E40<=5,"Restock Alert",IF(E40>50,"Overstock Alert","Stock Level OK")) -> Restock Alert
...

Sheet Sale by Month
A1: Row Labels | B1: Sum of Sales (Naira)
A2: Jan | B2: 43517380
A3: Feb | B3: 39014420
A4: Mar | B4: 38658540
A5: Apr | B5: 16436940
A6: May | B6: 16535680
A7: Jun | B7: 12672720
A8: Jul | B8: 15214970
A9: Aug | B9: 15425050
A10: Sep | B10: 16424350
A11: Oct | B11: 19579100
A12: Nov | B12: 16831380
A13: Dec | B13: 18706050
A14: Grand Total | B14: 269016580

Sheet Sales by Product
A1: Row Labels | B1: Sum of Sales (Naira)
A2: Antibiotics | B2: 324000
A3: Beans | B3: 71040000
A4: Biscuits | B4: 4570800
A5: Bread | B5: 902000
A6: Broom | B6: 95000
A7: Bucket | B7: 475000
A8: Butter | B8: 81000
A9: Cap | B9: 334000
A10: Chips | B10: 387600
A11: Chocolate | B11: 3000000
A12: Coffee | B12: 1495300
A13: Coke | B13: 2986560
... A50: Grand Total | B50: 269016580

Sheet Sales by Payment
A1: Row Labels | B1: Sum of Sales (Naira)
A2: Card | B2: 86885270
A3: Cash | B3: 87390950
A4: Transfer | B4: 94740360
A5: Grand Total | B5: 269016580

Sheet Sales by day
A1: Row Labels | B1: Sum of Sales (Naira) | C1: Sum of Quantity
A2: 1-Jan | B2: 1433380 | C2: 134
A3: 2-Jan | B3: 2077500 | C3: 136
A4: 3-Jan | B4: 525820 | C4: 103
A5: 4-Jan | B5: 1682080 | C5: 83
A6: 5-Jan | B6: 881260 | C6: 94
A7: 6-Jan | B7: 1497580 | C7: 101
A8: 7-Jan | B8: 895600 | C8: 148
A9: 8-Jan | B9: 3226720 | C9: 190
A10: 9-Jan | B10: 1182410 | C10: 115
A11: 10-Jan | B11: 1182830 | C11: 132
A12: 11-Jan | B12: 2244180 | C12: 104
A13: 12-Jan | B13: 1306700 | C13: 114
... A366: Grand Total | B366: 269016580 | C366: 27086

Sheet Sales by category
A3: Row Labels | B3: Sum of Sales (Naira)
A4: Beverages | B4: 9786930
A5: Clothing | B5: 8740000
A6: Dairy | B6: 6350900
A7: Electronics | B7: 4383500
A8: Food items | B8: 208519700
A9: Household | B9: 14930750
A10: Pharmaceuticals | B10: 1463000
A11: Snacks | B11: 7958400
A12: Sport | B12: 6883400
A13: Grand Total | B13: 269016580

Sheet Sheet9
A1: Row Labels | B1: Sum of Quantity | C1: Forecast(Sum of Quantity) | D1: Lower Confidence Bound(Sum of Quantity) | E1: Upper Confidence Bound(Sum of Quantity) | G1: Statistic | H1: Value
A2: 45658 | B2: 134 | G2: Alpha | H2: =_xlfn.FORECAST.ETS.STAT($B$2:$B$365,$A$2:$A$365,1,1,1) -> 0.126
A3: 45659 | B3: 136 | G3: Beta | H3: =_xlfn.FORECAST.ETS.STAT($B$2:$B$365,$A$2:$A$365,2,1,1) -> 0.001
A4: 45660 | B4: 103 | G4: Gamma | H4: =_xlfn.FORECAST.ETS.STAT($B$2:$B$365,$A$2:$A$365,3,1,1) -> 2.220446e-16
A5: 45661 | B5: 83 | G5: MASE | H5: =_xlfn.FORECAST.ETS.STAT($B$2:$B$365,$A$2:$A$365,4,1,1) -> 0.60658949
A6: 45662 | B6: 94 | G6: SMAPE | H6: =_xlfn.FORECAST.ETS.STAT($B$2:$B$365,$A$2:$A$365,5,1,1) -> 0.22837643
A7: 45663 | B7: 101 | G7: MAE | H7: =_xlfn.FORECAST.ETS.STAT($B$2:$B$365,$A$2:$A$365,6,1,1) -> 13.577146
A8: 45664 | B8: 148 | G8: RMSE | H8: =_xlfn.FORECAST.ETS.STAT($B$2:$B$365,$A$2:$A$365,7,1,1) -> 18.4071
A9: 45665 | B9: 190
A10: 45666 | B10: 114
A11: 45667 | B11: 132
A12: 45668 | B12: 104
A13: 45669 | B13: 114
A14: 45670 | B14: 127
A15: 45671 | B15: 107
A16: 45672 | B16: 141
A17: 45673 | B17: 134
A18: 45674 | B18: 130
A19: 45675 | B19: 116
A20: 45676 | B20: 137
... A364: 46020 | B364: 97
A365: 46021 | B365: 58 | C365: 58 | D365: 58 | E365: 58
A366: 46022 | C366: =_xlfn.FORECAST.ETS(A366,$B$2:$B$365,$A$2:$A$365,1,1) -> 68.223868 | D366: =C366-_xlfn.FORECAST.ETS.CONFINT(A366,$B$2:$B$365,$A$2:$A$365,0.8,1,1) -> 39.83887 | E366: =C366+_xlfn.FORECAST.ETS.CONFINT(A366,$B$2:$B$365,$A$2:$A$365,0.8,1,1) -> 96.608866
A367: 46023 | C367: =_xlfn.FORECAST.ETS(A367,$B$2:$B$365,$A$2:$A$365,1,1) -> 68.235856 | D367: =C367-_xlfn.FORECAST.ETS.CONFINT(A367,$B$2:$B$365,$A$2:$A$365,0.8,1,1) -> 39.622863 | E367: =C367+_xlfn.FORECAST.ETS.CONFINT(A367,$B$2:$B$365,$A$2:$A$365,0.8,1,1) -> 96.848849
A368: 46024 | C368: =_xlfn.FORECAST.ETS(A368,$B$2:$B$365,$A$2:$A$365,1,1) -> 68.247843 | D368: =C368-_xlfn.FORECAST.ETS.CONFINT(A368,$B$2:$B$365,$A$2:$A$365,0.8,1,1) -> 39.405096 | E368: =C368+_xlfn.FORECAST.ETS.CONFINT(A368,$B$2:$B$365,$A$2:$A$365,0.8,1,1) -> 97.090591
A369: 46025 | C369: =_xlfn.FORECAST.ETS(A369,$B$2:$B$365,$A$2:$A$365,1,1) -> 68.259831 | D369: =C369-_xlfn.FORECAST.ETS.CONFINT(A369,$B$2:$B$365,$A$2:$A$365,0.8,1,1) -> 39.185584 | E369: =C369+_xlfn.FORECAST.ETS.CONFINT(A369,$B$2:$B$365,$A$2:$A$365,0.8,1,1) -> 97.334079
A370: 46026 | C370: =_xlfn.FORECAST.ETS(A370,$B$2:$B$365,$A$2:$A$365,1,1) -> 68.271819 | D370: =C370-_xlfn.FORECAST.ETS.CONFINT(A370,$B$2:$B$365,$A$2:$A$365,0.8,1,1) -> 38.96434 | E370: =C370+_xlfn.FORECAST.ETS.CONFINT(A370,$B$2:$B$365,$A$2:$A$365,0.8,1,1) -> 97.579299
A371: 46027 | C371: =_xlfn.FORECAST.ETS(A371,$B$2:$B$365,$A$2:$A$365,1,1) -> 68.283807 | D371: =C371-_xlfn.FORECAST.ETS.CONFINT(A371,$B$2:$B$365,$A$2:$A$365,0.8,1,1) -> 38.741378 | E371: =C371+_xlfn.FORECAST.ETS.CONFINT(A371,$B$2:$B$365,$A$2:$A$365,0.8,1,1) -> 97.826236
A372: 46028 | C372: =_xlfn.FORECAST.ETS(A372,$B$2:$B$365,$A$2:$A$365,1,1) -> 68.295795 | D372: =C372-_xlfn.FORECAST.ETS.CONFINT(A372,$B$2:$B$365,$A$2:$A$365,0.8,1,1) -> 38.516712 | E372: =C372+_xlfn.FORECAST.ETS.CONFINT(A372,$B$2:$B$365,$A$2:$A$365,0.8,1,1) -> 98.074878
A373: 46029 | C373: =_xlfn.FORECAST.ETS(A373,$B$2:$B$365,$A$2:$A$365,1,1) -> 68.307783 | D373: =C373-_xlfn.FORECAST.ETS.CONFINT(A373,$B$2:$B$365,$A$2:$A$365,0.8,1,1) -> 38.290355 | E373: =C373+_xlfn.FORECAST.ETS.CONFINT(A373,$B$2:$B$365,$A$2:$A$365,0.8,1,1) -> 98.32521
A374: 46030 | C374: =_xlfn.FORECAST.ETS(A374,$B$2:$B$365,$A$2:$A$365,1,1) -> 68.319771 | D374: =C374-_xlfn.FORECAST.ETS.CONFINT(A374,$B$2:$B$365,$A$2:$A$365,0.8,1,1) -> 38.062321 | E374: =C374+_xlfn.FORECAST.ETS.CONFINT(A374,$B$2:$B$365,$A$2:$A$365,0.8,1,1) -> 98.57722
A375: 46031 | C375: =_xlfn.FORECAST.ETS(A375,$B$2:$B$365,$A$2:$A$365,1,1) -> 68.331758 | D375: =C375-_xlfn.FORECAST.ETS.CONFINT(A375,$B$2:$B$365,$A$2:$A$365,0.8,1,1) -> 37.832623 | E375: =C375+_xlfn.FORECAST.ETS.CONFINT(A375,$B$2:$B$365,$A$2:$A$365,0.8,1,1) -> 98.830894
A376: 46032 | C376: =_xlfn.FORECAST.ETS(A376,$B$2:$B$365,$A$2:$A$365,1,1) -> 68.343746 | D376: =C376-_xlfn.FORECAST.ETS.CONFINT(A376,$B$2:$B$365,$A$2:$A$365,0.8,1,1) -> 37.601273 | E376: =C376+_xlfn.FORECAST.ETS.CONFINT(A376,$B$2:$B$365,$A$2:$A$365,0.8,1,1) -> 99.086219
A377: 46033 | C377: =_xlfn.FORECAST.ETS(A377,$B$2:$B$365,$A$2:$A$365,1,1) -> 68.355734 | D377: =C377-_xlfn.FORECAST.ETS.CONFINT(A377,$B$2:$B$365,$A$2:$A$365,0.8,1,1) -> 37.368285 | E377: =C377+_xlfn.FORECAST.ETS.CONFINT(A377,$B$2:$B$365,$A$2:$A$365,0.8,1,1) -> 99.343183
... A397: 46053 | C397: =_xlfn.FORECAST.ETS(A397,$B$2:$B$365,$A$2:$A$365,1,1) -> 68.595491 | D397: =C397-_xlfn.FORECAST.ETS.CONFINT(A397,$B$2:$B$365,$A$2:$A$365,0.8,1,1) -> 32.383041 | E397: =C397+_xlfn.FORECAST.ETS.CONFINT(A397,$B$2:$B$365,$A$2:$A$365,0.8,1,1) -> 104.80794

Sheet ETS Forecast
A1: Row Labels | B1: Sum of Quantity | C1: ETS Approach | D1: ES Error | E1: Absolute Error | F1: Absolute Squared Error | G1: Absolute Percentage Error | H1: Total number of sales | I1: Average number of sale | L1: Sum of Sales (Naira)
A2: 45658 | B2: 134 | C2: 0.5 | D2: =B2-C2 -> 133.5 | E2: =ABS(D2) -> 133.5 | F2: =E2^2 -> 17822.25 | G2: =E2/B2 -> 0.99626866 | H2: =SUM(B:B) -> 27085 | I2: =H2/365 -> 74.205479 | L2: 1433380
A3: 45659 | B3: 136 | C3: 0.5 | D3: =B3-C3 -> 135.5 | E3: =ABS(D3) -> 135.5 | F3: =E3^2 -> 18360.25 | G3: =E3/B3 -> 0.99632353 | L3: 2077500
A4: 45660 | B4: 103 | C4: 0.5 | D4: =B4-C4 -> 102.5 | E4: =ABS(D4) -> 102.5 | F4: =E4^2 -> 10506.25 | G4: =E4/B4 -> 0.99514563 | L4: 525820
A5: 45661 | B5: 83 | C5: 0.5 | D5: =B5-C5 -> 82.5 | E5: =ABS(D5) -> 82.5 | F5: =E5^2 -> 6806.25 | G5: =E5/B5 -> 0.9939759 | L5: 1682080
A6: 45662 | B6: 94 | C6: 0.5 | D6: =B6-C6 -> 93.5 | E6: =ABS(D6) -> 93.5 | F6: =E6^2 -> 8742.25 | G6: =E6/B6 -> 0.99468085 | L6: 881260
A7: 45663 | B7: 101 | C7: 0.5 | D7: =B7-C7 -> 100.5 | E7: =ABS(D7) -> 100.5 | F7: =E7^2 -> 10100.25 | G7: =E7/B7 -> 0.9950495 | L7: 1497580
A8: 45664 | B8: 148 | C8: 0.5 | D8: =B8-C8 -> 147.5 | E8: =ABS(D8) -> 147.5 | F8: =E8^2 -> 21756.25 | G8: =E8/B8 -> 0.99662162 | J8: MAE | K8: =AVERAGE(E:E) -> 73.909341 | L8: 895600
A9: 45665 | B9: 190 | C9: 0.5 | D9: =B9-C9 -> 189.5 | E9: =ABS(D9) -> 189.5 | F9: =E9^2 -> 35910.25 | G9: =E9/B9 -> 0.99736842 | J9: MSE | K9: =AVERAGE(F:F) -> 6634.9313 | L9: 3226720
A10: 45666 | B10: 114 | C10: 0.5 | D10: =B10-C10 -> 113.5 | E10: =ABS(D10) -> 113.5 | F10: =E10^2 -> 12882.25 | G10: =E10/B10 -> 0.99561404 | J10: MAPE | K10: =AVERAGE(G:G) -> 0.99194576 | L10: 1182410
A11: 45667 | B11: 132 | C11: 0.5 | D11: =B11-C11 -> 131.5 | E11: =ABS(D11) -> 131.5 | F11: =E11^2 -> 17292.25 | G11: =E11/B11 -> 0.99621212 | J11: Accuracy | K11: =100-K10 -> 99.008054 | L11: 1182830
A12: 45668 | B12: 104 | C12: 0.5 | D12: =B12-C12 -> 103.5 | E12: =ABS(D12) -> 103.5 | F12: =E12^2 -> 10712.25 | G12: =E12/B12 -> 0.99519231 | L12: 2244180
A13: 45669 | B13: 114 | C13: 0.5 | D13: =B13-C13 -> 113.5 | E13: =ABS(D13) -> 113.5 | F13: =E13^2 -> 12882.25 | G13: =E13/B13 -> 0.99561404 | L13: 1306700
A14: 45670 | B14: 127 | C14: 0.5 | D14: =B14-C14 -> 126.5 | E14: =ABS(D14) -> 126.5 | F14: =E14^2 -> 16002.25 | G14: =E14/B14 -> 0.99606299 | L14: 813280
A15: 45671 | B15: 107 | C15: 0.5 | D15: =B15-C15 -> 106.5 | E15: =ABS(D15) -> 106.5 | F15: =E15^2 -> 11342.25 | G15: =E15/B15 -> 0.9953271 | L15: 1463800
A16: 45672 | B16: 141 | C16: 0.5 | D16: =B16-C16 -> 140.5 | E16: =ABS(D16) -> 140.5 | F16: =E16^2 -> 19740.25 | G16: =E16/B16 -> 0.9964539 | L16: 1492800
A17: 45673 | B17: 134 | C17: 0.5 | D17: =B17-C17 -> 133.5 | E17: =ABS(D17) -> 133.5 | F17: =E17^2 -> 17822.25 | G17: =E17/B17 -> 0.99626866 | L17: 1250350
A18: 45674 | B18: 130 | C18: 0.5 | D18: =B18-C18 -> 129.5 | E18: =ABS(D18) -> 129.5 | F18: =E18^2 -> 16770.25 | G18: =E18/B18 -> 0.99615385 | L18: 1703700
A19: 45675 | B19: 116 | C19: 0.5 | D19: =B19-C19 -> 115.5 | E19: =ABS(D19) -> 115.5 | F19: =E19^2 -> 13340.25 | G19: =E19/B19 -> 0.99568966 | L19: 898180
A20: 45676 | B20: 137 | C20: 0.5 | D20: =B20-C20 -> 136.5 | E20: =ABS(D20) -> 136.5 | F20: =E20^2 -> 18632.25 | G20: =E20/B20 -> 0.99635036 | L20: 2329080
A21: 45677 | B21: 123 | C21: 0.5 | D21: =B21-C21 -> 122.5 | E21: =ABS(D21) -> 122.5 | F21: =E21^2 -> 15006.25 | G21: =E21/B21 -> 0.99593496 | L21: 888080
A22: 45678 | B22: 100 | C22: 0.5 | D22: =B22-C22 -> 99.5 | E22: =ABS(D22) -> 99.5 | F22: =E22^2 -> 9900.25 | G22: =E22/B22 -> 0.995 | L22: 803630
A23: 45679 | B23: 89 | C23: 0.5 | D23: =B23-C23 -> 88.5 | E23: =ABS(D23) -> 88.5 | F23: =E23^2 -> 7832.25 | G23: =E23/B23 -> 0.99438202 | L23: 652070
... A365: 46021 | B365: 58 | C365: 0.5 | D365: =B365-C365 -> 57.5 | E365: =ABS(D365) -> 57.5 | F365: =E365^2 -> 3306.25 | G365: =E365/B365 -> 0.99137931 | L365: 176720
L366: 269016580

Sheet Sales Data
A1: Invoice ID | B1: Date | C1: Category | D1: Product | E1: Unit Price (Naira) | F1: Quantity | G1: Sales (Naira) | H1: Payment | I1: COGS (Naira) | J1: Gross Income(Naira)
A2: INV0001 | B2: 45658 | C2: Food items | D2: Beans | E2: 60000 | F2: 3 | G2: =E2*F2 -> 180000 | H2: Cash | I2: =E2*1.2 -> 72000 | J2: =I2*F2 -> 216000
A3: INV0002 | B3: 45658 | C3: Snacks | D3: Chips | E3: 400 | F3: 5 | G3: =E3*F3 -> 2000 | H3: Cash | I3: =E3*1.2 -> 480 | J3: =I3*F3 -> 2400
A4: INV0003 | B4: 45658 | C4: Beverages | D4: Fanta | E4: 2880 | F4: 1 | G4: =E4*F4 -> 2880 | H4: Cash | I4: =E4*1.2 -> 3456 | J4: =I4*F4 -> 3456
A5: INV0004 | B5: 45658 | C5: Household | D5: Toothpaste | E5: 800 | F5: 6 | G5: =E5*F5 -> 4800 | H5: Cash | I5: =E5*1.2 -> 960 | J5: =I5*F5 -> 5760
A6: INV0005 | B6: 45658 | C6: Household | D6: Shampoo | E6: 1200 | F6: 3 | G6: =E6*F6 -> 3600 | H6: Card | I6: =E6*1.2 -> 1440 | J6: =I6*F6 -> 4320
A7: INV0006 | B7: 45658 | C7: Snacks | D7: Chocolate | E7: 3000 | F7: 6 | G7: =E7*F7 -> 18000 | H7: Card | I7: =E7*1.2 -> 3600 | J7: =I7*F7 -> 21600
A8: INV0007 | B8: 45658 | C8: Beverages | D8: Pepsi | E8: 2880 | F8: 2 | G8: =E8*F8 -> 5760 | H8: Transfer | I8: =E8*1.2 -> 3456 | J8: =I8*F8 -> 6912
A9: INV0008 | B9: 45658 | C9: Beverages | D9: Pepsi | E9: 2880 | F9: 3 | G9: =E9*F9 -> 8640 | H9: Transfer | I9: =E9*1.2 -> 3456 | J9: =I9*F9 -> 10368
A10: INV0009 | B10: 45658 | C10: Household | D10: Shampoo | E10: 1200 | F10: 5 | G10: =E10*F10 -> 6000 | H10: Cash | I10: =E10*1.2 -> 1440 | J10: =I10*F10 -> 7200
A11: INV0010 | B11: 45658 | C11: Snacks | D11: Biscuits | E11: 5200 | F11: 2 | G11: =E11*F11 -> 10400 | H11: Transfer | I11: =E11*1.2 -> 6240 | J11: =I11*F11 -> 12480
A12: INV2878 | B12: 45658 | C12: Food items | D12: Eggs | E12: 3300 | F12: 5 | G12: =E12*F12 -> 16500 | H12: Transfer | I12: =E12*1.2 -> 3960 | J12: =I12*F12 -> 19800
A13: INV3087 | B13: 45658 | C13: Food items | D13: Bread | E13: 500 | F13: 10 | G13: =E13*F13 -> 5000 | H13: Card | I13: =E13*1.2 -> 600 | J13: =I13*F13 -> 6000
... A97: INV3798 | B97: 45662 | C97: Food items | D97: Eggs | E97: 3300 | F97: 3 | G97: =E97*F97 -> 9900 | H97: Card | I97: =E97*1.2 -> 3960 | J97: =I97*F97 -> 11880
A98: INV3948 | B98: 45662 | C98: Pharmaceuticals | D98: Antibiotics | E98: 2000 | F98: 7 | G98: =E98*F98 -> 14000 | H98: Transfer | I98: =E98*1.2 -> 2400 | J98: =I98*F98 -> 16800 | K98: =SUMIF(D:D,"Antibiotics",F:F) -> 162
A99: INV4054 | B99: 45662 | C99: Clothing | D99: T-shirt | E99: 8000 | F99: 6 | G99: =E99*F99 -> 48000 | H99: Transfer | I99: =E99*1.2 -> 9600 | J99: =I99*F99 -> 57600
A100: INV4191 | B100: 45662 | C100: Household | D100: Detergent | E100: 6900 | F100: 4 | G100: =E100*F100 -> 27600 | H100: Card | I100: =E100*1.2 -> 8280 | J100: =I100*F100 -> 33120
A101: INV4216 | B101: 45662 | C101: Household | D101: Toilet Paper | E101: 4000 | F101: 4 | G101: =E101*F101 -> 16000 | H101: Card | I101: =E101*1.2 -> 4800 | J101: =I101*F101 -> 19200
A102: INV4324 | B102: 45662 | C102: Household | D102: Toilet Paper | E102: 4000 | F102: 9 | G102: =E102*F102 -> 36000 | H102: Transfer | I102: =E102*1.2 -> 4800 | J102: =I102*F102 -> 43200
A103: INV4449 | B103: 45662 | C103: Clothing | D103: Shoes | E103: 15000 | F103: 1 | G103: =E103*F103 -> 15000 | H103: Cash | I103: =E103*1.2 -> 18000 | J103: =I103*F103 -> 18000
A104: INV4459 | B104: 45662 | C104: Household | D104: Bucket | E104: 2500 | F104: 5 | G104: =E104*F104 -> 12500 | H104: Transfer | I104: =E104*1.2 -> 3000 | J104: =I104*F104 -> 15000
A105: INV4484 | B105: 45662 | C105: Clothing | D105: Cap | E105: 2000 | F105: 1 | G105: =E105*F105 -> 2000 | H105: Card | I105: =E105*1.2 -> 2400 | J105: =I105*F105 -> 2400
A106: INV4492 | B106: 45662 | C106: Food items | D106: Garri | E106: 35000 | F106: 1 | G106: =E106*F106 -> 35000 | H106: Transfer | I106: =E106*1.2 -> 42000 | J106: =I106*F106 -> 42000
A107: INV4714 | B107: 45662 | C107: Clothing | D107: Shoes | E107: 15000 | F107: 3 | G107: =E107*F107 -> 45000 | H107: Transfer | I107: =E107*1.2 -> 18000 | J107: =I107*F107 -> 54000
A108: INV4884 | B108: 45662 | C108: Pharmaceuticals | D108: Vitamin C | E108: 1000 | F108: 7 | G108: =E108*F108 -> 7000 | H108: Transfer | I108: =E108*1.2 -> 1200 | J108: =I108*F108 -> 8400
A109: INV4893 | B109: 45662 | C109: Electronics | D109: LED Bulb | E109: 500 | F109: 7 | G109: =E109*F109 -> 3500 | H109: Transfer | I109: =E109*1.2 -> 600 | J109: =I109*F109 -> 4200
A110: INV0046 | B110: 45663 | C110: Beverages | D110: Coke | E110: 2880 | F110: 1 | G110: =E110*F110 -> 2880 | H110: Transfer | I110: =E110*1.2 -> 3456 | J110: =I110*F110 -> 3456
... A218: INV3278 | B218: 45667 | C218: Dairy | D218: Milk | E218: 9100 | F218: 9 | G218: =E218*F218 -> 81900 | H218: Transfer | I218: =E218*1.2 -> 10920 | J218: =I218*F218 -> 98280
A219: INV3433 | B219: 45667 | C219: Food items | D219: Eggs | E219: 3300 | F219: 3 | G219: =E219*F219 -> 9900 | H219: Cash | I219: =E219*1.2 -> 3960 | J219: =I219*F219 -> 11880 | K219: =SUMIF(D:D,"Eggs",F:F) -> 628
A220: INV3861 | B220: 45667 | C220: Food items | D220: Bread | E220: 500 | F220: 1 | G220: =E220*F220 -> 500 | H220: Transfer | I220: =E220*1.2 -> 600 | J220: =I220*F220 -> 600
A221: INV3956 | B221: 45667 | C221: Pharmaceuticals | D221: Antibiotics | E221: 2000 | F221: 2 | G221: =E221*F221 -> 4000 | H221: Cash | I221: =E221*1.2 -> 2400 | J221: =I221*F221 -> 4800
A222: INV3980 | B222: 45667 | C222: Sport | D222: Jersey | E222: 13000 | F222: 8 | G222: =E222*F222 -> 104000 | H222: Transfer | I222: =E222*1.2 -> 15600 | J222: =I222*F222 -> 124800
A223: INV4040 | B223: 45667 | C223: Sport | D223: Running Shoes | E223: 15000 | F223: 7 | G223: =E223*F223 -> 105000 | H223: Transfer | I223: =E223*1.2 -> 18000 | J223: =I223*F223 -> 126000
A224: INV4245 | B224: 45667 | C224: Household | D224: Detergent | E224: 6900 | F224: 6 | G224: =E224*F224 -> 41400 | H224: Cash | I224: =E224*1.2 -> 8280 | J224: =I224*F224 -> 49680
A225: INV4265 | B225: 45667 | C225: Electronics | D225: LED Bulb | E225: 500 | F225: 5 | G225: =E225*F225 -> 2500 | H225: Transfer | I225: =E225*1.2 -> 600 | J225: =I225*F225 -> 3000
A226: INV4516 | B226: 45667 | C226: Clothing | D226: T-shirt | E226: 8000 | F226: 7 | G226: =E226*F226 -> 56000 | H226: Cash | I226: =E226*1.2 -> 9600 | J226: =I226*F226 -> 67200
A227: INV4871 | B227: 45667 | C227: Sport | D227: Running Shoes | E227: 15000 | F227: 7 | G227: =E227*F227 -> 105000 | H227: Transfer | I227: =E227*1.2 -> 18000 | J227: =I227*F227 -> 126000
A228: INV4873 | B228: 45667 | C228: Electronics | D228: Power Bank | E228: 12000 | F228: 4 | G228: =E228*F228 -> 48000 | H228: Card | I228: =E228*1.2 -> 14400 | J228: =I228*F228 -> 57600
A229: INV4904 | B229: 45667 | C229: Food items | D229: Rice | E229: 48000 | F229: 9 | G229: =E229*F229 -> 432000 | H229: Card | I229: =E229*1.2 -> 57600 | J229: =I229*F229 -> 518400
A230: INV0088 | B230: 45668 | C230: Household | D230: Toothpaste | E230: 800 | F230: 10 | G230: =E230*F230 -> 8000 | H230: Transfer | I230: =E230*1.2 -> 960 | J230: =I230*F230 -> 9600
...
